Assuming unrestricted shared filesystem usage.
None
host: MacBookAir.lan
Building DAG of jobs...
Using shell: /bin/bash
Provided cores: 1 (use --cores to define parallelism)
Rules claiming more threads will be scaled down.
Job stats:
job                count
---------------  -------
random_guessing        1
total                  1

Select jobs to execute...
Execute 1 jobs...
[Sat May 10 20:31:05 2025]
localrule random_guessing:
    output: RANDOM_GUESSING-Results.txt
    jobid: 0
    reason: Missing output files: RANDOM_GUESSING-Results.txt
    resources: tmpdir=/var/folders/zq/9vmc9tbn5pv_0b8_c7ffd6nh0000gn/T

Traceback (most recent call last):

  File "/Library/Frameworks/Python.framework/Versions/3.13/lib/python3.13/site-packages/snakemake/executors/local.py", line 232, in spawn_job
    subprocess.check_call(cmd, shell=True)
    ~~~~~~~~~~~~~~~~~~~~~^^^^^^^^^^^^^^^^^

  File "/Library/Frameworks/Python.framework/Versions/3.13/lib/python3.13/subprocess.py", line 421, in check_call
    raise CalledProcessError(retcode, cmd)

subprocess.CalledProcessError: Command 'cd /Users/samuelgair/Desktop/BA_code/snakemake_fun && /Library/Frameworks/Python.framework/Versions/3.13/bin/python3.13 -m snakemake --snakefile '/Users/samuelgair/Desktop/BA_code/snakemake_fun/workflow/Snakefile' --target-jobs 'random_guessing:' --allowed-rules random_guessing --cores 1 --attempt 1 --force-use-threads  --force --target-files-omit-workdir-adjustment --max-inventory-time 0 --nocolor --notemp --no-hooks --nolock --ignore-incomplete --rerun-triggers input software-env params code mtime --conda-frontend 'conda' --shared-fs-usage input-output source-cache sources software-deployment persistence storage-local-copies --wrapper-prefix 'https://github.com/snakemake/snakemake-wrappers/raw/' --latency-wait 5 --scheduler 'greedy' --local-storage-prefix base64//LnNuYWtlbWFrZS9zdG9yYWdl --scheduler-solver-path '/Library/Frameworks/Python.framework/Versions/3.13/bin' --default-resources base64//dG1wZGlyPXN5c3RlbV90bXBkaXI= --quiet progress rules host --mode 'subprocess' --local-groupid 'local'' returned non-zero exit status 1.


During handling of the above exception, another exception occurred:


Traceback (most recent call last):

  File "/Library/Frameworks/Python.framework/Versions/3.13/lib/python3.13/concurrent/futures/thread.py", line 59, in run
    result = self.fn(*self.args, **self.kwargs)

  File "/Library/Frameworks/Python.framework/Versions/3.13/lib/python3.13/site-packages/snakemake/executors/local.py", line 247, in cached_or_run
    run_func(*args)
    ~~~~~~~~^^^^^^^

  File "/Library/Frameworks/Python.framework/Versions/3.13/lib/python3.13/site-packages/snakemake/executors/local.py", line 234, in spawn_job
    raise SpawnedJobError()

snakemake.exceptions.SpawnedJobError

[Sat May 10 20:31:07 2025]
Error in rule random_guessing:
    message: None
    jobid: 0
    output: RANDOM_GUESSING-Results.txt
Shutting down, this might take some time.
Exiting because a job execution failed. Look below for error messages
[Sat May 10 20:31:07 2025]
Error in rule random_guessing:
    message: None
    jobid: 0
    output: RANDOM_GUESSING-Results.txt
Complete log(s): /Users/samuelgair/Desktop/BA_code/snakemake_fun/.snakemake/log/2025-05-10T203105.838898.snakemake.log
WorkflowError:
At least one job did not complete successfully.
