Assuming unrestricted shared filesystem usage.
None
host: student-net-rz-1815.intern.ethz.ch
Building DAG of jobs...
Using shell: /bin/bash
Provided cores: 1 (use --cores to define parallelism)
Rules claiming more threads will be scaled down.
Job stats:
job                count
---------------  -------
some_other_rule        1
total                  1

Select jobs to execute...
Execute 1 jobs...
[Tue May  6 10:03:40 2025]
localrule some_other_rule:
    input: output.txt
    output: healthy_sample_imputed.txt
    jobid: 0
    reason: Missing output files: healthy_sample_imputed.txt
    resources: tmpdir=/var/folders/zq/9vmc9tbn5pv_0b8_c7ffd6nh0000gn/T

Traceback (most recent call last):

  File "/Library/Frameworks/Python.framework/Versions/3.13/lib/python3.13/site-packages/snakemake/executors/local.py", line 232, in spawn_job
    subprocess.check_call(cmd, shell=True)
    ~~~~~~~~~~~~~~~~~~~~~^^^^^^^^^^^^^^^^^

  File "/Library/Frameworks/Python.framework/Versions/3.13/lib/python3.13/subprocess.py", line 421, in check_call
    raise CalledProcessError(retcode, cmd)

subprocess.CalledProcessError: Command 'cd /Users/samuelgair/Desktop/BA_code/snakemake_fun && /Library/Frameworks/Python.framework/Versions/3.13/bin/python3.13 -m snakemake --snakefile '/Users/samuelgair/Desktop/BA_code/snakemake_fun/workflow/Snakefile' --target-jobs 'some_other_rule:' --allowed-rules some_other_rule --cores 1 --attempt 1 --force-use-threads  --force --target-files-omit-workdir-adjustment --max-inventory-time 0 --nocolor --notemp --no-hooks --nolock --ignore-incomplete --rerun-triggers input software-env code mtime params --conda-frontend 'conda' --shared-fs-usage source-cache persistence input-output sources storage-local-copies software-deployment --wrapper-prefix 'https://github.com/snakemake/snakemake-wrappers/raw/' --latency-wait 5 --scheduler 'greedy' --local-storage-prefix base64//LnNuYWtlbWFrZS9zdG9yYWdl --scheduler-solver-path '/Library/Frameworks/Python.framework/Versions/3.13/bin' --default-resources base64//dG1wZGlyPXN5c3RlbV90bXBkaXI= --quiet progress rules host --mode 'subprocess' --local-groupid 'local'' returned non-zero exit status 1.


During handling of the above exception, another exception occurred:


Traceback (most recent call last):

  File "/Library/Frameworks/Python.framework/Versions/3.13/lib/python3.13/concurrent/futures/thread.py", line 59, in run
    result = self.fn(*self.args, **self.kwargs)

  File "/Library/Frameworks/Python.framework/Versions/3.13/lib/python3.13/site-packages/snakemake/executors/local.py", line 247, in cached_or_run
    run_func(*args)
    ~~~~~~~~^^^^^^^

  File "/Library/Frameworks/Python.framework/Versions/3.13/lib/python3.13/site-packages/snakemake/executors/local.py", line 234, in spawn_job
    raise SpawnedJobError()

snakemake.exceptions.SpawnedJobError

[Tue May  6 10:03:41 2025]
Error in rule some_other_rule:
    message: None
    jobid: 0
    input: output.txt
    output: healthy_sample_imputed.txt
Shutting down, this might take some time.
Exiting because a job execution failed. Look below for error messages
[Tue May  6 10:03:41 2025]
Error in rule some_other_rule:
    message: None
    jobid: 0
    input: output.txt
    output: healthy_sample_imputed.txt
Complete log(s): /Users/samuelgair/Desktop/BA_code/snakemake_fun/.snakemake/log/2025-05-06T100340.284269.snakemake.log
WorkflowError:
At least one job did not complete successfully.
